[2025-05-16T00:15:25.816+0000] {taskinstance.py:1956} INFO - Dependencies all met for dep_context=non-requeueable deps ti=<TaskInstance: breweries_etl_pipeline.transform_to_silver scheduled__2025-05-15T00:00:00+00:00 [queued]>
[2025-05-16T00:15:25.844+0000] {taskinstance.py:1956} INFO - Dependencies all met for dep_context=requeueable deps ti=<TaskInstance: breweries_etl_pipeline.transform_to_silver scheduled__2025-05-15T00:00:00+00:00 [queued]>
[2025-05-16T00:15:25.846+0000] {taskinstance.py:2170} INFO - Starting attempt 3 of 6
[2025-05-16T00:15:25.917+0000] {taskinstance.py:2191} INFO - Executing <Task(PythonOperator): transform_to_silver> on 2025-05-15 00:00:00+00:00
[2025-05-16T00:15:25.930+0000] {standard_task_runner.py:60} INFO - Started process 652 to run task
[2025-05-16T00:15:25.937+0000] {standard_task_runner.py:87} INFO - Running: ['***', 'tasks', 'run', 'breweries_etl_pipeline', 'transform_to_silver', 'scheduled__2025-05-15T00:00:00+00:00', '--job-id', '220', '--raw', '--subdir', 'DAGS_FOLDER/breweries_pipeline.py', '--cfg-path', '/tmp/tmp5ngxox0i']
[2025-05-16T00:15:25.940+0000] {standard_task_runner.py:88} INFO - Job 220: Subtask transform_to_silver
[2025-05-16T00:15:25.978+0000] {warnings.py:109} WARNING - /home/***/.local/lib/python3.8/site-packages/***/settings.py:194: DeprecationWarning: The sql_alchemy_conn option in [core] has been moved to the sql_alchemy_conn option in [database] - the old setting has been used, but please update your config.
  SQL_ALCHEMY_CONN = conf.get("database", "SQL_ALCHEMY_CONN")

[2025-05-16T00:15:26.076+0000] {task_command.py:423} INFO - Running <TaskInstance: breweries_etl_pipeline.transform_to_silver scheduled__2025-05-15T00:00:00+00:00 [running]> on host dd755db511a0
[2025-05-16T00:15:26.516+0000] {taskinstance.py:2480} INFO - Exporting env vars: AIRFLOW_CTX_DAG_OWNER='***' AIRFLOW_CTX_DAG_ID='breweries_etl_pipeline' AIRFLOW_CTX_TASK_ID='transform_to_silver' AIRFLOW_CTX_EXECUTION_DATE='2025-05-15T00:00:00+00:00' AIRFLOW_CTX_TRY_NUMBER='3' AIRFLOW_CTX_DAG_RUN_ID='scheduled__2025-05-15T00:00:00+00:00'
[2025-05-16T00:15:26.592+0000] {logging_mixin.py:188} INFO - üîπ Iniciando transforma√ß√£o dos dados (Bronze ‚ûù Silver)
[2025-05-16T00:22:31.410+0000] {local_task_job_runner.py:121} ERROR - Received SIGTERM. Terminating subprocesses
[2025-05-16T00:22:31.413+0000] {process_utils.py:131} INFO - Sending 15 to group 652. PIDs of all processes in the group: [654, 652]
[2025-05-16T00:22:31.414+0000] {process_utils.py:86} INFO - Sending the signal 15 to group 652
[2025-05-16T00:22:31.416+0000] {taskinstance.py:2450} ERROR - Received SIGTERM. Terminating subprocesses.
[2025-05-16T00:22:31.428+0000] {clientserver.py:538} INFO - Error while receiving.
Traceback (most recent call last):
  File "/home/airflow/.local/lib/python3.8/site-packages/py4j/clientserver.py", line 511, in send_command
    answer = smart_decode(self.stream.readline()[:-1])
  File "/usr/local/lib/python3.8/socket.py", line 669, in readinto
    return self._sock.recv_into(b)
  File "/home/airflow/.local/lib/python3.8/site-packages/airflow/models/taskinstance.py", line 2452, in signal_handler
    raise AirflowException("Task received SIGTERM signal")
airflow.exceptions.AirflowException: Task received SIGTERM signal
[2025-05-16T00:22:31.482+0000] {clientserver.py:543} INFO - Closing down clientserver connection
[2025-05-16T00:22:31.486+0000] {java_gateway.py:1055} ERROR - Exception while sending command.
Traceback (most recent call last):
  File "/home/airflow/.local/lib/python3.8/site-packages/py4j/clientserver.py", line 511, in send_command
    answer = smart_decode(self.stream.readline()[:-1])
  File "/usr/local/lib/python3.8/socket.py", line 669, in readinto
    return self._sock.recv_into(b)
  File "/home/airflow/.local/lib/python3.8/site-packages/airflow/models/taskinstance.py", line 2452, in signal_handler
    raise AirflowException("Task received SIGTERM signal")
airflow.exceptions.AirflowException: Task received SIGTERM signal

During handling of the above exception, another exception occurred:

Traceback (most recent call last):
  File "/home/airflow/.local/lib/python3.8/site-packages/py4j/java_gateway.py", line 1038, in send_command
    response = connection.send_command(command)
  File "/home/airflow/.local/lib/python3.8/site-packages/py4j/clientserver.py", line 539, in send_command
    raise Py4JNetworkError(
py4j.protocol.Py4JNetworkError: Error while sending or receiving
[2025-05-16T00:22:31.494+0000] {clientserver.py:543} INFO - Closing down clientserver connection
[2025-05-16T00:22:31.498+0000] {taskinstance.py:2698} ERROR - Task failed with exception
Traceback (most recent call last):
  File "/home/airflow/.local/lib/python3.8/site-packages/airflow/models/taskinstance.py", line 433, in _execute_task
    result = execute_callable(context=context, **execute_callable_kwargs)
  File "/home/airflow/.local/lib/python3.8/site-packages/airflow/operators/python.py", line 199, in execute
    return_value = self.execute_callable()
  File "/home/airflow/.local/lib/python3.8/site-packages/airflow/operators/python.py", line 216, in execute_callable
    return self.python_callable(*self.op_args, **self.op_kwargs)
  File "/opt/airflow/dags/src/transform.py", line 22, in transform_to_silver
    df = spark.read.json(json_file)
  File "/home/airflow/.local/lib/python3.8/site-packages/pyspark/sql/readwriter.py", line 284, in json
    return self._df(self._jreader.json(self._spark._sc._jvm.PythonUtils.toSeq(path)))
  File "/home/airflow/.local/lib/python3.8/site-packages/py4j/java_gateway.py", line 1321, in __call__
    return_value = get_return_value(
  File "/home/airflow/.local/lib/python3.8/site-packages/pyspark/sql/utils.py", line 190, in deco
    return f(*a, **kw)
  File "/home/airflow/.local/lib/python3.8/site-packages/py4j/protocol.py", line 334, in get_return_value
    raise Py4JError(
py4j.protocol.Py4JError: An error occurred while calling o46.json
[2025-05-16T00:22:31.645+0000] {taskinstance.py:1138} INFO - Marking task as UP_FOR_RETRY. dag_id=breweries_etl_pipeline, task_id=transform_to_silver, execution_date=20250515T000000, start_date=20250516T001525, end_date=20250516T002231
[2025-05-16T00:22:31.804+0000] {standard_task_runner.py:107} ERROR - Failed to execute job 220 for task transform_to_silver (An error occurred while calling o46.json; 652)
[2025-05-16T00:22:31.968+0000] {process_utils.py:79} INFO - Process psutil.Process(pid=652, status='terminated', exitcode=1, started='00:15:25') (652) terminated with exit code 1
[2025-05-16T00:22:33.122+0000] {process_utils.py:79} INFO - Process psutil.Process(pid=654, status='terminated', started='00:15:26') (654) terminated with exit code None
[2025-05-16T00:22:33.127+0000] {local_task_job_runner.py:234} INFO - Task exited with return code 143
[2025-05-16T00:22:33.255+0000] {taskinstance.py:3280} INFO - 0 downstream tasks scheduled from follow-on schedule check
