[2025-05-16T09:04:49.890+0000] {taskinstance.py:1956} INFO - Dependencies all met for dep_context=non-requeueable deps ti=<TaskInstance: breweries_etl_pipeline.extract_breweries manual__2025-05-16T09:04:46.437449+00:00 [queued]>
[2025-05-16T09:04:49.897+0000] {taskinstance.py:1956} INFO - Dependencies all met for dep_context=requeueable deps ti=<TaskInstance: breweries_etl_pipeline.extract_breweries manual__2025-05-16T09:04:46.437449+00:00 [queued]>
[2025-05-16T09:04:49.898+0000] {taskinstance.py:2170} INFO - Starting attempt 1 of 6
[2025-05-16T09:04:49.906+0000] {taskinstance.py:2191} INFO - Executing <Task(PythonOperator): extract_breweries> on 2025-05-16 09:04:46.437449+00:00
[2025-05-16T09:04:49.918+0000] {standard_task_runner.py:60} INFO - Started process 55 to run task
[2025-05-16T09:04:49.924+0000] {standard_task_runner.py:87} INFO - Running: ['***', 'tasks', 'run', 'breweries_etl_pipeline', 'extract_breweries', 'manual__2025-05-16T09:04:46.437449+00:00', '--job-id', '3', '--raw', '--subdir', 'DAGS_FOLDER/breweries_pipeline.py', '--cfg-path', '/tmp/tmpl2dwd3pd']
[2025-05-16T09:04:49.926+0000] {standard_task_runner.py:88} INFO - Job 3: Subtask extract_breweries
[2025-05-16T09:04:50.121+0000] {warnings.py:109} WARNING - /home/***/.local/lib/python3.8/site-packages/***/settings.py:194: DeprecationWarning: The sql_alchemy_conn option in [core] has been moved to the sql_alchemy_conn option in [database] - the old setting has been used, but please update your config.
  SQL_ALCHEMY_CONN = conf.get("database", "SQL_ALCHEMY_CONN")

[2025-05-16T09:04:50.175+0000] {task_command.py:423} INFO - Running <TaskInstance: breweries_etl_pipeline.extract_breweries manual__2025-05-16T09:04:46.437449+00:00 [running]> on host af93bbb00882
[2025-05-16T09:04:50.256+0000] {taskinstance.py:2480} INFO - Exporting env vars: AIRFLOW_CTX_DAG_OWNER='***' AIRFLOW_CTX_DAG_ID='breweries_etl_pipeline' AIRFLOW_CTX_TASK_ID='extract_breweries' AIRFLOW_CTX_EXECUTION_DATE='2025-05-16T09:04:46.437449+00:00' AIRFLOW_CTX_TRY_NUMBER='1' AIRFLOW_CTX_DAG_RUN_ID='manual__2025-05-16T09:04:46.437449+00:00'
[2025-05-16T09:04:50.268+0000] {logging_mixin.py:188} INFO - 游댳 Iniciando extra칞칚o de dados da API Open Brewery DB
[2025-05-16T09:04:51.309+0000] {logging_mixin.py:188} INFO - 九덢잺 P치gina 1 extra칤da com 200 registros
[2025-05-16T09:04:52.417+0000] {logging_mixin.py:188} INFO - 九덢잺 P치gina 2 extra칤da com 200 registros
[2025-05-16T09:04:53.542+0000] {logging_mixin.py:188} INFO - 九덢잺 P치gina 3 extra칤da com 200 registros
[2025-05-16T09:04:54.562+0000] {logging_mixin.py:188} INFO - 九덢잺 P치gina 4 extra칤da com 200 registros
[2025-05-16T09:04:55.592+0000] {logging_mixin.py:188} INFO - 九덢잺 P치gina 5 extra칤da com 200 registros
[2025-05-16T09:04:56.713+0000] {logging_mixin.py:188} INFO - 九덢잺 P치gina 6 extra칤da com 200 registros
[2025-05-16T09:04:57.752+0000] {logging_mixin.py:188} INFO - 九덢잺 P치gina 7 extra칤da com 200 registros
[2025-05-16T09:04:58.835+0000] {logging_mixin.py:188} INFO - 九덢잺 P치gina 8 extra칤da com 200 registros
[2025-05-16T09:04:59.878+0000] {logging_mixin.py:188} INFO - 九덢잺 P치gina 9 extra칤da com 200 registros
[2025-05-16T09:05:00.904+0000] {logging_mixin.py:188} INFO - 九덢잺 P치gina 10 extra칤da com 200 registros
[2025-05-16T09:05:01.933+0000] {logging_mixin.py:188} INFO - 九덢잺 P치gina 11 extra칤da com 200 registros
[2025-05-16T09:05:02.955+0000] {logging_mixin.py:188} INFO - 九덢잺 P치gina 12 extra칤da com 200 registros
[2025-05-16T09:05:04.004+0000] {logging_mixin.py:188} INFO - 九덢잺 P치gina 13 extra칤da com 200 registros
[2025-05-16T09:05:05.222+0000] {logging_mixin.py:188} INFO - 九덢잺 P치gina 14 extra칤da com 200 registros
[2025-05-16T09:05:06.332+0000] {logging_mixin.py:188} INFO - 九덢잺 P치gina 15 extra칤da com 200 registros
[2025-05-16T09:05:07.336+0000] {logging_mixin.py:188} INFO - 九덢잺 P치gina 16 extra칤da com 200 registros
[2025-05-16T09:05:08.327+0000] {logging_mixin.py:188} INFO - 九덢잺 P치gina 17 extra칤da com 200 registros
[2025-05-16T09:05:09.304+0000] {logging_mixin.py:188} INFO - 九덢잺 P치gina 18 extra칤da com 200 registros
[2025-05-16T09:05:10.258+0000] {logging_mixin.py:188} INFO - 九덢잺 P치gina 19 extra칤da com 200 registros
[2025-05-16T09:05:11.354+0000] {logging_mixin.py:188} INFO - 九덢잺 P치gina 20 extra칤da com 200 registros
[2025-05-16T09:05:12.357+0000] {logging_mixin.py:188} INFO - 九덢잺 P치gina 21 extra칤da com 200 registros
[2025-05-16T09:05:13.357+0000] {logging_mixin.py:188} INFO - 九덢잺 P치gina 22 extra칤da com 200 registros
[2025-05-16T09:05:14.424+0000] {logging_mixin.py:188} INFO - 九덢잺 P치gina 23 extra칤da com 200 registros
[2025-05-16T09:05:15.578+0000] {logging_mixin.py:188} INFO - 九덢잺 P치gina 24 extra칤da com 200 registros
[2025-05-16T09:05:16.678+0000] {logging_mixin.py:188} INFO - 九덢잺 P치gina 25 extra칤da com 200 registros
[2025-05-16T09:05:17.728+0000] {logging_mixin.py:188} INFO - 九덢잺 P치gina 26 extra칤da com 200 registros
[2025-05-16T09:05:18.843+0000] {logging_mixin.py:188} INFO - 九덢잺 P치gina 27 extra칤da com 200 registros
[2025-05-16T09:05:19.911+0000] {logging_mixin.py:188} INFO - 九덢잺 P치gina 28 extra칤da com 200 registros
[2025-05-16T09:05:20.878+0000] {logging_mixin.py:188} INFO - 九덢잺 P치gina 29 extra칤da com 200 registros
[2025-05-16T09:05:21.904+0000] {logging_mixin.py:188} INFO - 九덢잺 P치gina 30 extra칤da com 200 registros
[2025-05-16T09:05:22.964+0000] {logging_mixin.py:188} INFO - 九덢잺 P치gina 31 extra칤da com 200 registros
[2025-05-16T09:05:23.571+0000] {logging_mixin.py:188} INFO - 九덢잺 P치gina 32 extra칤da com 200 registros
[2025-05-16T09:05:24.567+0000] {logging_mixin.py:188} INFO - 九덢잺 P치gina 33 extra칤da com 200 registros
[2025-05-16T09:05:25.588+0000] {logging_mixin.py:188} INFO - 九덢잺 P치gina 34 extra칤da com 200 registros
[2025-05-16T09:05:26.510+0000] {logging_mixin.py:188} INFO - 九덢잺 P치gina 35 extra칤da com 200 registros
[2025-05-16T09:05:27.524+0000] {logging_mixin.py:188} INFO - 九덢잺 P치gina 36 extra칤da com 200 registros
[2025-05-16T09:05:28.557+0000] {logging_mixin.py:188} INFO - 九덢잺 P치gina 37 extra칤da com 200 registros
[2025-05-16T09:05:29.782+0000] {logging_mixin.py:188} INFO - 九덢잺 P치gina 38 extra칤da com 200 registros
[2025-05-16T09:05:30.914+0000] {logging_mixin.py:188} INFO - 九덢잺 P치gina 39 extra칤da com 200 registros
[2025-05-16T09:05:31.940+0000] {logging_mixin.py:188} INFO - 九덢잺 P치gina 40 extra칤da com 200 registros
[2025-05-16T09:05:32.843+0000] {logging_mixin.py:188} INFO - 九덢잺 P치gina 41 extra칤da com 200 registros
[2025-05-16T09:05:33.915+0000] {logging_mixin.py:188} INFO - 九덢잺 P치gina 42 extra칤da com 170 registros
[2025-05-16T09:05:43.954+0000] {taskinstance.py:2698} ERROR - Task failed with exception
Traceback (most recent call last):
  File "/home/airflow/.local/lib/python3.8/site-packages/urllib3/connectionpool.py", line 715, in urlopen
    httplib_response = self._make_request(
  File "/home/airflow/.local/lib/python3.8/site-packages/urllib3/connectionpool.py", line 416, in _make_request
    conn.request(method, url, **httplib_request_kw)
  File "/home/airflow/.local/lib/python3.8/site-packages/botocore/awsrequest.py", line 96, in request
    rval = super().request(method, url, body, headers, *args, **kwargs)
  File "/home/airflow/.local/lib/python3.8/site-packages/urllib3/connection.py", line 244, in request
    super(HTTPConnection, self).request(method, url, body=body, headers=headers)
  File "/usr/local/lib/python3.8/http/client.py", line 1256, in request
    self._send_request(method, url, body, headers, encode_chunked)
  File "/usr/local/lib/python3.8/http/client.py", line 1302, in _send_request
    self.endheaders(body, encode_chunked=encode_chunked)
  File "/usr/local/lib/python3.8/http/client.py", line 1251, in endheaders
    self._send_output(message_body, encode_chunked=encode_chunked)
  File "/home/airflow/.local/lib/python3.8/site-packages/botocore/awsrequest.py", line 130, in _send_output
    self._handle_expect_response(message_body)
  File "/home/airflow/.local/lib/python3.8/site-packages/botocore/awsrequest.py", line 176, in _handle_expect_response
    self._send_message_body(message_body)
  File "/home/airflow/.local/lib/python3.8/site-packages/botocore/awsrequest.py", line 209, in _send_message_body
    self.send(message_body)
  File "/home/airflow/.local/lib/python3.8/site-packages/botocore/awsrequest.py", line 223, in send
    return super().send(str)
  File "/usr/local/lib/python3.8/http/client.py", line 969, in send
    self.sock.sendall(datablock)
ConnectionResetError: [Errno 104] Connection reset by peer

During handling of the above exception, another exception occurred:

Traceback (most recent call last):
  File "/home/airflow/.local/lib/python3.8/site-packages/botocore/httpsession.py", line 464, in send
    urllib_response = conn.urlopen(
  File "/home/airflow/.local/lib/python3.8/site-packages/urllib3/connectionpool.py", line 799, in urlopen
    retries = retries.increment(
  File "/home/airflow/.local/lib/python3.8/site-packages/urllib3/util/retry.py", line 525, in increment
    raise six.reraise(type(error), error, _stacktrace)
  File "/home/airflow/.local/lib/python3.8/site-packages/urllib3/packages/six.py", line 769, in reraise
    raise value.with_traceback(tb)
  File "/home/airflow/.local/lib/python3.8/site-packages/urllib3/connectionpool.py", line 715, in urlopen
    httplib_response = self._make_request(
  File "/home/airflow/.local/lib/python3.8/site-packages/urllib3/connectionpool.py", line 416, in _make_request
    conn.request(method, url, **httplib_request_kw)
  File "/home/airflow/.local/lib/python3.8/site-packages/botocore/awsrequest.py", line 96, in request
    rval = super().request(method, url, body, headers, *args, **kwargs)
  File "/home/airflow/.local/lib/python3.8/site-packages/urllib3/connection.py", line 244, in request
    super(HTTPConnection, self).request(method, url, body=body, headers=headers)
  File "/usr/local/lib/python3.8/http/client.py", line 1256, in request
    self._send_request(method, url, body, headers, encode_chunked)
  File "/usr/local/lib/python3.8/http/client.py", line 1302, in _send_request
    self.endheaders(body, encode_chunked=encode_chunked)
  File "/usr/local/lib/python3.8/http/client.py", line 1251, in endheaders
    self._send_output(message_body, encode_chunked=encode_chunked)
  File "/home/airflow/.local/lib/python3.8/site-packages/botocore/awsrequest.py", line 130, in _send_output
    self._handle_expect_response(message_body)
  File "/home/airflow/.local/lib/python3.8/site-packages/botocore/awsrequest.py", line 176, in _handle_expect_response
    self._send_message_body(message_body)
  File "/home/airflow/.local/lib/python3.8/site-packages/botocore/awsrequest.py", line 209, in _send_message_body
    self.send(message_body)
  File "/home/airflow/.local/lib/python3.8/site-packages/botocore/awsrequest.py", line 223, in send
    return super().send(str)
  File "/usr/local/lib/python3.8/http/client.py", line 969, in send
    self.sock.sendall(datablock)
urllib3.exceptions.ProtocolError: ('Connection aborted.', ConnectionResetError(104, 'Connection reset by peer'))

During handling of the above exception, another exception occurred:

Traceback (most recent call last):
  File "/home/airflow/.local/lib/python3.8/site-packages/airflow/models/taskinstance.py", line 433, in _execute_task
    result = execute_callable(context=context, **execute_callable_kwargs)
  File "/home/airflow/.local/lib/python3.8/site-packages/airflow/operators/python.py", line 199, in execute
    return_value = self.execute_callable()
  File "/home/airflow/.local/lib/python3.8/site-packages/airflow/operators/python.py", line 216, in execute_callable
    return self.python_callable(*self.op_args, **self.op_kwargs)
  File "/opt/airflow/dags/src/extract.py", line 38, in extract_breweries
    upload_to_s3(
  File "/opt/airflow/dags/src/s3_utils.py", line 26, in upload_to_s3
    s3.put_object(Bucket=bucket, Key=key, Body=body)
  File "/home/airflow/.local/lib/python3.8/site-packages/botocore/client.py", line 553, in _api_call
    return self._make_api_call(operation_name, kwargs)
  File "/home/airflow/.local/lib/python3.8/site-packages/botocore/client.py", line 989, in _make_api_call
    http, parsed_response = self._make_request(
  File "/home/airflow/.local/lib/python3.8/site-packages/botocore/client.py", line 1015, in _make_request
    return self._endpoint.make_request(operation_model, request_dict)
  File "/home/airflow/.local/lib/python3.8/site-packages/botocore/endpoint.py", line 119, in make_request
    return self._send_request(request_dict, operation_model)
  File "/home/airflow/.local/lib/python3.8/site-packages/botocore/endpoint.py", line 202, in _send_request
    while self._needs_retry(
  File "/home/airflow/.local/lib/python3.8/site-packages/botocore/endpoint.py", line 354, in _needs_retry
    responses = self._event_emitter.emit(
  File "/home/airflow/.local/lib/python3.8/site-packages/botocore/hooks.py", line 412, in emit
    return self._emitter.emit(aliased_event_name, **kwargs)
  File "/home/airflow/.local/lib/python3.8/site-packages/botocore/hooks.py", line 256, in emit
    return self._emit(event_name, kwargs)
  File "/home/airflow/.local/lib/python3.8/site-packages/botocore/hooks.py", line 239, in _emit
    response = handler(**kwargs)
  File "/home/airflow/.local/lib/python3.8/site-packages/botocore/retryhandler.py", line 207, in __call__
    if self._checker(**checker_kwargs):
  File "/home/airflow/.local/lib/python3.8/site-packages/botocore/retryhandler.py", line 284, in __call__
    should_retry = self._should_retry(
  File "/home/airflow/.local/lib/python3.8/site-packages/botocore/retryhandler.py", line 320, in _should_retry
    return self._checker(attempt_number, response, caught_exception)
  File "/home/airflow/.local/lib/python3.8/site-packages/botocore/retryhandler.py", line 363, in __call__
    checker_response = checker(
  File "/home/airflow/.local/lib/python3.8/site-packages/botocore/retryhandler.py", line 247, in __call__
    return self._check_caught_exception(
  File "/home/airflow/.local/lib/python3.8/site-packages/botocore/retryhandler.py", line 416, in _check_caught_exception
    raise caught_exception
  File "/home/airflow/.local/lib/python3.8/site-packages/botocore/endpoint.py", line 281, in _do_get_response
    http_response = self._send(request)
  File "/home/airflow/.local/lib/python3.8/site-packages/botocore/endpoint.py", line 377, in _send
    return self.http_session.send(request)
  File "/home/airflow/.local/lib/python3.8/site-packages/botocore/httpsession.py", line 503, in send
    raise ConnectionClosedError(
botocore.exceptions.ConnectionClosedError: Connection was closed before we received a valid response from endpoint URL: "http://minio:9000/bronze/breweries_raw_20250516.json".
[2025-05-16T09:05:43.973+0000] {taskinstance.py:1138} INFO - Marking task as UP_FOR_RETRY. dag_id=breweries_etl_pipeline, task_id=extract_breweries, execution_date=20250516T090446, start_date=20250516T090449, end_date=20250516T090543
[2025-05-16T09:05:43.987+0000] {standard_task_runner.py:107} ERROR - Failed to execute job 3 for task extract_breweries (Connection was closed before we received a valid response from endpoint URL: "http://minio:9000/bronze/breweries_raw_20250516.json".; 55)
[2025-05-16T09:05:44.033+0000] {local_task_job_runner.py:234} INFO - Task exited with return code 1
[2025-05-16T09:05:44.059+0000] {taskinstance.py:3280} INFO - 0 downstream tasks scheduled from follow-on schedule check
