[2025-05-15T23:51:45.012+0000] {taskinstance.py:1956} INFO - Dependencies all met for dep_context=non-requeueable deps ti=<TaskInstance: breweries_etl_pipeline.extract_breweries scheduled__2025-05-14T00:00:00+00:00 [queued]>
[2025-05-15T23:51:45.037+0000] {taskinstance.py:1956} INFO - Dependencies all met for dep_context=requeueable deps ti=<TaskInstance: breweries_etl_pipeline.extract_breweries scheduled__2025-05-14T00:00:00+00:00 [queued]>
[2025-05-15T23:51:45.038+0000] {taskinstance.py:2170} INFO - Starting attempt 2 of 6
[2025-05-15T23:51:45.077+0000] {taskinstance.py:2191} INFO - Executing <Task(PythonOperator): extract_breweries> on 2025-05-14 00:00:00+00:00
[2025-05-15T23:51:45.090+0000] {standard_task_runner.py:60} INFO - Started process 8668 to run task
[2025-05-15T23:51:45.100+0000] {standard_task_runner.py:87} INFO - Running: ['***', 'tasks', 'run', 'breweries_etl_pipeline', 'extract_breweries', 'scheduled__2025-05-14T00:00:00+00:00', '--job-id', '208', '--raw', '--subdir', 'DAGS_FOLDER/breweries_pipeline.py', '--cfg-path', '/tmp/tmpd9p7h6d0']
[2025-05-15T23:51:45.103+0000] {standard_task_runner.py:88} INFO - Job 208: Subtask extract_breweries
[2025-05-15T23:51:45.141+0000] {warnings.py:109} WARNING - /home/***/.local/lib/python3.8/site-packages/***/settings.py:194: DeprecationWarning: The sql_alchemy_conn option in [core] has been moved to the sql_alchemy_conn option in [database] - the old setting has been used, but please update your config.
  SQL_ALCHEMY_CONN = conf.get("database", "SQL_ALCHEMY_CONN")

[2025-05-15T23:51:45.245+0000] {task_command.py:423} INFO - Running <TaskInstance: breweries_etl_pipeline.extract_breweries scheduled__2025-05-14T00:00:00+00:00 [running]> on host dd755db511a0
[2025-05-15T23:51:45.467+0000] {taskinstance.py:2480} INFO - Exporting env vars: AIRFLOW_CTX_DAG_OWNER='***' AIRFLOW_CTX_DAG_ID='breweries_etl_pipeline' AIRFLOW_CTX_TASK_ID='extract_breweries' AIRFLOW_CTX_EXECUTION_DATE='2025-05-14T00:00:00+00:00' AIRFLOW_CTX_TRY_NUMBER='2' AIRFLOW_CTX_DAG_RUN_ID='scheduled__2025-05-14T00:00:00+00:00'
[2025-05-15T23:51:45.472+0000] {logging_mixin.py:188} INFO - 游댳 Iniciando extra칞칚o de dados da API Open Brewery DB
[2025-05-15T23:51:48.483+0000] {logging_mixin.py:188} INFO - 九덢잺 P치gina 1 extra칤da com 200 registros
[2025-05-15T23:51:57.288+0000] {logging_mixin.py:188} INFO - 九덢잺 P치gina 2 extra칤da com 200 registros
[2025-05-15T23:51:58.440+0000] {logging_mixin.py:188} INFO - 九덢잺 P치gina 3 extra칤da com 200 registros
[2025-05-15T23:52:15.936+0000] {logging_mixin.py:188} INFO - 九덢잺 P치gina 4 extra칤da com 200 registros
[2025-05-15T23:52:23.674+0000] {logging_mixin.py:188} INFO - 九덢잺 P치gina 5 extra칤da com 200 registros
[2025-05-15T23:52:24.631+0000] {logging_mixin.py:188} INFO - 九덢잺 P치gina 6 extra칤da com 200 registros
[2025-05-15T23:52:38.985+0000] {logging_mixin.py:188} INFO - 九덢잺 P치gina 7 extra칤da com 200 registros
[2025-05-15T23:52:42.182+0000] {logging_mixin.py:188} INFO - 九덢잺 P치gina 8 extra칤da com 200 registros
[2025-05-15T23:52:46.048+0000] {logging_mixin.py:188} INFO - 九덢잺 P치gina 9 extra칤da com 200 registros
[2025-05-15T23:53:16.534+0000] {logging_mixin.py:188} INFO - 九덢잺 P치gina 10 extra칤da com 200 registros
[2025-05-15T23:53:17.547+0000] {logging_mixin.py:188} INFO - 九덢잺 P치gina 11 extra칤da com 200 registros
[2025-05-15T23:53:18.694+0000] {logging_mixin.py:188} INFO - 九덢잺 P치gina 12 extra칤da com 200 registros
[2025-05-15T23:53:21.779+0000] {logging_mixin.py:188} INFO - 九덢잺 P치gina 13 extra칤da com 200 registros
[2025-05-15T23:53:22.675+0000] {logging_mixin.py:188} INFO - 九덢잺 P치gina 14 extra칤da com 200 registros
[2025-05-15T23:53:23.617+0000] {logging_mixin.py:188} INFO - 九덢잺 P치gina 15 extra칤da com 200 registros
[2025-05-15T23:53:25.721+0000] {logging_mixin.py:188} INFO - 九덢잺 P치gina 16 extra칤da com 200 registros
[2025-05-15T23:53:39.139+0000] {logging_mixin.py:188} INFO - 九덢잺 P치gina 17 extra칤da com 200 registros
[2025-05-15T23:53:44.537+0000] {logging_mixin.py:188} INFO - 九덢잺 P치gina 18 extra칤da com 200 registros
[2025-05-15T23:53:49.467+0000] {logging_mixin.py:188} INFO - 九덢잺 P치gina 19 extra칤da com 200 registros
[2025-05-15T23:53:50.324+0000] {logging_mixin.py:188} INFO - 九덢잺 P치gina 20 extra칤da com 200 registros
[2025-05-15T23:54:26.034+0000] {logging_mixin.py:188} INFO - 九덢잺 P치gina 21 extra칤da com 200 registros
[2025-05-15T23:54:28.265+0000] {logging_mixin.py:188} INFO - 九덢잺 P치gina 22 extra칤da com 200 registros
[2025-05-15T23:54:30.622+0000] {logging_mixin.py:188} INFO - 九덢잺 P치gina 23 extra칤da com 200 registros
[2025-05-15T23:54:31.807+0000] {logging_mixin.py:188} INFO - 九덢잺 P치gina 24 extra칤da com 200 registros
[2025-05-15T23:54:41.832+0000] {logging_mixin.py:188} INFO - 九덢잺 P치gina 25 extra칤da com 200 registros
[2025-05-15T23:54:42.990+0000] {logging_mixin.py:188} INFO - 九덢잺 P치gina 26 extra칤da com 200 registros
[2025-05-15T23:54:44.096+0000] {logging_mixin.py:188} INFO - 九덢잺 P치gina 27 extra칤da com 200 registros
[2025-05-15T23:54:46.047+0000] {logging_mixin.py:188} INFO - 九덢잺 P치gina 28 extra칤da com 200 registros
[2025-05-15T23:54:49.590+0000] {logging_mixin.py:188} INFO - 九덢잺 P치gina 29 extra칤da com 200 registros
[2025-05-15T23:54:51.611+0000] {logging_mixin.py:188} INFO - 九덢잺 P치gina 30 extra칤da com 200 registros
[2025-05-15T23:54:52.573+0000] {logging_mixin.py:188} INFO - 九덢잺 P치gina 31 extra칤da com 200 registros
[2025-05-15T23:54:54.703+0000] {logging_mixin.py:188} INFO - 九덢잺 P치gina 32 extra칤da com 200 registros
[2025-05-15T23:54:55.945+0000] {logging_mixin.py:188} INFO - 九덢잺 P치gina 33 extra칤da com 200 registros
[2025-05-15T23:54:56.951+0000] {logging_mixin.py:188} INFO - 九덢잺 P치gina 34 extra칤da com 200 registros
[2025-05-15T23:55:04.961+0000] {taskinstance.py:2698} ERROR - Task failed with exception
Traceback (most recent call last):
  File "/home/airflow/.local/lib/python3.8/site-packages/urllib3/connection.py", line 174, in _new_conn
    conn = connection.create_connection(
  File "/home/airflow/.local/lib/python3.8/site-packages/urllib3/util/connection.py", line 72, in create_connection
    for res in socket.getaddrinfo(host, port, family, socket.SOCK_STREAM):
  File "/usr/local/lib/python3.8/socket.py", line 918, in getaddrinfo
    for res in _socket.getaddrinfo(host, port, family, type, proto, flags):
socket.gaierror: [Errno -3] Temporary failure in name resolution

During handling of the above exception, another exception occurred:

Traceback (most recent call last):
  File "/home/airflow/.local/lib/python3.8/site-packages/urllib3/connectionpool.py", line 715, in urlopen
    httplib_response = self._make_request(
  File "/home/airflow/.local/lib/python3.8/site-packages/urllib3/connectionpool.py", line 404, in _make_request
    self._validate_conn(conn)
  File "/home/airflow/.local/lib/python3.8/site-packages/urllib3/connectionpool.py", line 1058, in _validate_conn
    conn.connect()
  File "/home/airflow/.local/lib/python3.8/site-packages/urllib3/connection.py", line 363, in connect
    self.sock = conn = self._new_conn()
  File "/home/airflow/.local/lib/python3.8/site-packages/urllib3/connection.py", line 186, in _new_conn
    raise NewConnectionError(
urllib3.exceptions.NewConnectionError: <urllib3.connection.HTTPSConnection object at 0x7f6cde10e850>: Failed to establish a new connection: [Errno -3] Temporary failure in name resolution

During handling of the above exception, another exception occurred:

Traceback (most recent call last):
  File "/home/airflow/.local/lib/python3.8/site-packages/requests/adapters.py", line 486, in send
    resp = conn.urlopen(
  File "/home/airflow/.local/lib/python3.8/site-packages/urllib3/connectionpool.py", line 799, in urlopen
    retries = retries.increment(
  File "/home/airflow/.local/lib/python3.8/site-packages/urllib3/util/retry.py", line 592, in increment
    raise MaxRetryError(_pool, url, error or ResponseError(cause))
urllib3.exceptions.MaxRetryError: HTTPSConnectionPool(host='api.openbrewerydb.org', port=443): Max retries exceeded with url: /v1/breweries?page=35&per_page=200 (Caused by NewConnectionError('<urllib3.connection.HTTPSConnection object at 0x7f6cde10e850>: Failed to establish a new connection: [Errno -3] Temporary failure in name resolution'))

During handling of the above exception, another exception occurred:

Traceback (most recent call last):
  File "/home/airflow/.local/lib/python3.8/site-packages/airflow/models/taskinstance.py", line 433, in _execute_task
    result = execute_callable(context=context, **execute_callable_kwargs)
  File "/home/airflow/.local/lib/python3.8/site-packages/airflow/operators/python.py", line 199, in execute
    return_value = self.execute_callable()
  File "/home/airflow/.local/lib/python3.8/site-packages/airflow/operators/python.py", line 216, in execute_callable
    return self.python_callable(*self.op_args, **self.op_kwargs)
  File "/opt/airflow/dags/src/extract.py", line 23, in extract_breweries
    response = requests.get(API_URL, params={"page": page, "per_page": per_page})
  File "/home/airflow/.local/lib/python3.8/site-packages/requests/api.py", line 73, in get
    return request("get", url, params=params, **kwargs)
  File "/home/airflow/.local/lib/python3.8/site-packages/requests/api.py", line 59, in request
    return session.request(method=method, url=url, **kwargs)
  File "/home/airflow/.local/lib/python3.8/site-packages/requests/sessions.py", line 589, in request
    resp = self.send(prep, **send_kwargs)
  File "/home/airflow/.local/lib/python3.8/site-packages/requests/sessions.py", line 703, in send
    r = adapter.send(request, **kwargs)
  File "/home/airflow/.local/lib/python3.8/site-packages/requests/adapters.py", line 519, in send
    raise ConnectionError(e, request=request)
requests.exceptions.ConnectionError: HTTPSConnectionPool(host='api.openbrewerydb.org', port=443): Max retries exceeded with url: /v1/breweries?page=35&per_page=200 (Caused by NewConnectionError('<urllib3.connection.HTTPSConnection object at 0x7f6cde10e850>: Failed to establish a new connection: [Errno -3] Temporary failure in name resolution'))
[2025-05-15T23:55:04.998+0000] {taskinstance.py:1138} INFO - Marking task as UP_FOR_RETRY. dag_id=breweries_etl_pipeline, task_id=extract_breweries, execution_date=20250514T000000, start_date=20250515T235145, end_date=20250515T235504
[2025-05-15T23:55:05.035+0000] {standard_task_runner.py:107} ERROR - Failed to execute job 208 for task extract_breweries (HTTPSConnectionPool(host='api.openbrewerydb.org', port=443): Max retries exceeded with url: /v1/breweries?page=35&per_page=200 (Caused by NewConnectionError('<urllib3.connection.HTTPSConnection object at 0x7f6cde10e850>: Failed to establish a new connection: [Errno -3] Temporary failure in name resolution')); 8668)
[2025-05-15T23:55:05.077+0000] {local_task_job_runner.py:234} INFO - Task exited with return code 1
[2025-05-15T23:55:05.175+0000] {taskinstance.py:3280} INFO - 0 downstream tasks scheduled from follow-on schedule check
