[2025-05-15T23:49:26.382+0000] {taskinstance.py:1956} INFO - Dependencies all met for dep_context=non-requeueable deps ti=<TaskInstance: breweries_etl_pipeline.extract_breweries scheduled__2025-05-14T00:00:00+00:00 [queued]>
[2025-05-15T23:49:26.408+0000] {taskinstance.py:1956} INFO - Dependencies all met for dep_context=requeueable deps ti=<TaskInstance: breweries_etl_pipeline.extract_breweries scheduled__2025-05-14T00:00:00+00:00 [queued]>
[2025-05-15T23:49:26.409+0000] {taskinstance.py:2170} INFO - Starting attempt 1 of 6
[2025-05-15T23:49:26.479+0000] {taskinstance.py:2191} INFO - Executing <Task(PythonOperator): extract_breweries> on 2025-05-14 00:00:00+00:00
[2025-05-15T23:49:26.493+0000] {standard_task_runner.py:60} INFO - Started process 8665 to run task
[2025-05-15T23:49:26.503+0000] {standard_task_runner.py:87} INFO - Running: ['***', 'tasks', 'run', 'breweries_etl_pipeline', 'extract_breweries', 'scheduled__2025-05-14T00:00:00+00:00', '--job-id', '207', '--raw', '--subdir', 'DAGS_FOLDER/breweries_pipeline.py', '--cfg-path', '/tmp/tmp3nynp50p']
[2025-05-15T23:49:26.506+0000] {standard_task_runner.py:88} INFO - Job 207: Subtask extract_breweries
[2025-05-15T23:49:26.544+0000] {warnings.py:109} WARNING - /home/***/.local/lib/python3.8/site-packages/***/settings.py:194: DeprecationWarning: The sql_alchemy_conn option in [core] has been moved to the sql_alchemy_conn option in [database] - the old setting has been used, but please update your config.
  SQL_ALCHEMY_CONN = conf.get("database", "SQL_ALCHEMY_CONN")

[2025-05-15T23:49:26.659+0000] {task_command.py:423} INFO - Running <TaskInstance: breweries_etl_pipeline.extract_breweries scheduled__2025-05-14T00:00:00+00:00 [running]> on host dd755db511a0
[2025-05-15T23:49:27.415+0000] {taskinstance.py:2480} INFO - Exporting env vars: AIRFLOW_CTX_DAG_OWNER='***' AIRFLOW_CTX_DAG_ID='breweries_etl_pipeline' AIRFLOW_CTX_TASK_ID='extract_breweries' AIRFLOW_CTX_EXECUTION_DATE='2025-05-14T00:00:00+00:00' AIRFLOW_CTX_TRY_NUMBER='1' AIRFLOW_CTX_DAG_RUN_ID='scheduled__2025-05-14T00:00:00+00:00'
[2025-05-15T23:49:27.419+0000] {logging_mixin.py:188} INFO - ðŸ”¹ Iniciando extraÃ§Ã£o de dados da API Open Brewery DB
[2025-05-15T23:50:41.114+0000] {taskinstance.py:2698} ERROR - Task failed with exception
Traceback (most recent call last):
  File "/home/airflow/.local/lib/python3.8/site-packages/urllib3/connectionpool.py", line 715, in urlopen
    httplib_response = self._make_request(
  File "/home/airflow/.local/lib/python3.8/site-packages/urllib3/connectionpool.py", line 404, in _make_request
    self._validate_conn(conn)
  File "/home/airflow/.local/lib/python3.8/site-packages/urllib3/connectionpool.py", line 1058, in _validate_conn
    conn.connect()
  File "/home/airflow/.local/lib/python3.8/site-packages/urllib3/connection.py", line 419, in connect
    self.sock = ssl_wrap_socket(
  File "/home/airflow/.local/lib/python3.8/site-packages/urllib3/util/ssl_.py", line 449, in ssl_wrap_socket
    ssl_sock = _ssl_wrap_socket_impl(
  File "/home/airflow/.local/lib/python3.8/site-packages/urllib3/util/ssl_.py", line 493, in _ssl_wrap_socket_impl
    return ssl_context.wrap_socket(sock, server_hostname=server_hostname)
  File "/usr/local/lib/python3.8/ssl.py", line 500, in wrap_socket
    return self.sslsocket_class._create(
  File "/usr/local/lib/python3.8/ssl.py", line 1073, in _create
    self.do_handshake()
  File "/usr/local/lib/python3.8/ssl.py", line 1342, in do_handshake
    self._sslobj.do_handshake()
ssl.SSLZeroReturnError: TLS/SSL connection has been closed (EOF) (_ssl.c:1131)

During handling of the above exception, another exception occurred:

Traceback (most recent call last):
  File "/home/airflow/.local/lib/python3.8/site-packages/requests/adapters.py", line 486, in send
    resp = conn.urlopen(
  File "/home/airflow/.local/lib/python3.8/site-packages/urllib3/connectionpool.py", line 799, in urlopen
    retries = retries.increment(
  File "/home/airflow/.local/lib/python3.8/site-packages/urllib3/util/retry.py", line 592, in increment
    raise MaxRetryError(_pool, url, error or ResponseError(cause))
urllib3.exceptions.MaxRetryError: HTTPSConnectionPool(host='api.openbrewerydb.org', port=443): Max retries exceeded with url: /v1/breweries?page=1&per_page=200 (Caused by SSLError(SSLZeroReturnError(6, 'TLS/SSL connection has been closed (EOF) (_ssl.c:1131)')))

During handling of the above exception, another exception occurred:

Traceback (most recent call last):
  File "/home/airflow/.local/lib/python3.8/site-packages/airflow/models/taskinstance.py", line 433, in _execute_task
    result = execute_callable(context=context, **execute_callable_kwargs)
  File "/home/airflow/.local/lib/python3.8/site-packages/airflow/operators/python.py", line 199, in execute
    return_value = self.execute_callable()
  File "/home/airflow/.local/lib/python3.8/site-packages/airflow/operators/python.py", line 216, in execute_callable
    return self.python_callable(*self.op_args, **self.op_kwargs)
  File "/opt/airflow/dags/src/extract.py", line 23, in extract_breweries
    response = requests.get(API_URL, params={"page": page, "per_page": per_page})
  File "/home/airflow/.local/lib/python3.8/site-packages/requests/api.py", line 73, in get
    return request("get", url, params=params, **kwargs)
  File "/home/airflow/.local/lib/python3.8/site-packages/requests/api.py", line 59, in request
    return session.request(method=method, url=url, **kwargs)
  File "/home/airflow/.local/lib/python3.8/site-packages/requests/sessions.py", line 589, in request
    resp = self.send(prep, **send_kwargs)
  File "/home/airflow/.local/lib/python3.8/site-packages/requests/sessions.py", line 703, in send
    r = adapter.send(request, **kwargs)
  File "/home/airflow/.local/lib/python3.8/site-packages/requests/adapters.py", line 517, in send
    raise SSLError(e, request=request)
requests.exceptions.SSLError: HTTPSConnectionPool(host='api.openbrewerydb.org', port=443): Max retries exceeded with url: /v1/breweries?page=1&per_page=200 (Caused by SSLError(SSLZeroReturnError(6, 'TLS/SSL connection has been closed (EOF) (_ssl.c:1131)')))
[2025-05-15T23:50:41.228+0000] {taskinstance.py:1138} INFO - Marking task as UP_FOR_RETRY. dag_id=breweries_etl_pipeline, task_id=extract_breweries, execution_date=20250514T000000, start_date=20250515T234926, end_date=20250515T235041
[2025-05-15T23:50:41.260+0000] {standard_task_runner.py:107} ERROR - Failed to execute job 207 for task extract_breweries (HTTPSConnectionPool(host='api.openbrewerydb.org', port=443): Max retries exceeded with url: /v1/breweries?page=1&per_page=200 (Caused by SSLError(SSLZeroReturnError(6, 'TLS/SSL connection has been closed (EOF) (_ssl.c:1131)'))); 8665)
[2025-05-15T23:50:41.280+0000] {local_task_job_runner.py:234} INFO - Task exited with return code 1
[2025-05-15T23:50:41.345+0000] {taskinstance.py:3280} INFO - 0 downstream tasks scheduled from follow-on schedule check
