[2025-05-16T00:15:25.816+0000] {taskinstance.py:1956} INFO - Dependencies all met for dep_context=non-requeueable deps ti=<TaskInstance: breweries_etl_pipeline.aggregate_to_gold scheduled__2025-05-14T00:00:00+00:00 [queued]>
[2025-05-16T00:15:25.848+0000] {taskinstance.py:1956} INFO - Dependencies all met for dep_context=requeueable deps ti=<TaskInstance: breweries_etl_pipeline.aggregate_to_gold scheduled__2025-05-14T00:00:00+00:00 [queued]>
[2025-05-16T00:15:25.849+0000] {taskinstance.py:2170} INFO - Starting attempt 3 of 6
[2025-05-16T00:15:25.920+0000] {taskinstance.py:2191} INFO - Executing <Task(PythonOperator): aggregate_to_gold> on 2025-05-14 00:00:00+00:00
[2025-05-16T00:15:25.931+0000] {standard_task_runner.py:60} INFO - Started process 653 to run task
[2025-05-16T00:15:25.937+0000] {standard_task_runner.py:87} INFO - Running: ['***', 'tasks', 'run', 'breweries_etl_pipeline', 'aggregate_to_gold', 'scheduled__2025-05-14T00:00:00+00:00', '--job-id', '221', '--raw', '--subdir', 'DAGS_FOLDER/breweries_pipeline.py', '--cfg-path', '/tmp/tmpzjy0s01h']
[2025-05-16T00:15:25.941+0000] {standard_task_runner.py:88} INFO - Job 221: Subtask aggregate_to_gold
[2025-05-16T00:15:25.975+0000] {warnings.py:109} WARNING - /home/***/.local/lib/python3.8/site-packages/***/settings.py:194: DeprecationWarning: The sql_alchemy_conn option in [core] has been moved to the sql_alchemy_conn option in [database] - the old setting has been used, but please update your config.
  SQL_ALCHEMY_CONN = conf.get("database", "SQL_ALCHEMY_CONN")

[2025-05-16T00:15:26.076+0000] {task_command.py:423} INFO - Running <TaskInstance: breweries_etl_pipeline.aggregate_to_gold scheduled__2025-05-14T00:00:00+00:00 [running]> on host dd755db511a0
[2025-05-16T00:15:26.431+0000] {taskinstance.py:2480} INFO - Exporting env vars: AIRFLOW_CTX_DAG_OWNER='***' AIRFLOW_CTX_DAG_ID='breweries_etl_pipeline' AIRFLOW_CTX_TASK_ID='aggregate_to_gold' AIRFLOW_CTX_EXECUTION_DATE='2025-05-14T00:00:00+00:00' AIRFLOW_CTX_TRY_NUMBER='3' AIRFLOW_CTX_DAG_RUN_ID='scheduled__2025-05-14T00:00:00+00:00'
[2025-05-16T00:15:26.435+0000] {logging_mixin.py:188} INFO - üîπ Iniciando agrega√ß√£o dos dados (Silver ‚ûù Gold)
[2025-05-16T00:22:31.411+0000] {local_task_job_runner.py:121} ERROR - Received SIGTERM. Terminating subprocesses
[2025-05-16T00:22:31.418+0000] {process_utils.py:131} INFO - Sending 15 to group 653. PIDs of all processes in the group: [655, 653]
[2025-05-16T00:22:31.430+0000] {process_utils.py:86} INFO - Sending the signal 15 to group 653
[2025-05-16T00:22:31.444+0000] {taskinstance.py:2450} ERROR - Received SIGTERM. Terminating subprocesses.
[2025-05-16T00:22:31.470+0000] {clientserver.py:538} INFO - Error while receiving.
Traceback (most recent call last):
  File "/home/airflow/.local/lib/python3.8/site-packages/py4j/clientserver.py", line 511, in send_command
    answer = smart_decode(self.stream.readline()[:-1])
  File "/usr/local/lib/python3.8/socket.py", line 669, in readinto
    return self._sock.recv_into(b)
  File "/home/airflow/.local/lib/python3.8/site-packages/airflow/models/taskinstance.py", line 2452, in signal_handler
    raise AirflowException("Task received SIGTERM signal")
airflow.exceptions.AirflowException: Task received SIGTERM signal
[2025-05-16T00:22:31.479+0000] {clientserver.py:543} INFO - Closing down clientserver connection
[2025-05-16T00:22:31.480+0000] {java_gateway.py:1055} ERROR - Exception while sending command.
Traceback (most recent call last):
  File "/home/airflow/.local/lib/python3.8/site-packages/py4j/clientserver.py", line 511, in send_command
    answer = smart_decode(self.stream.readline()[:-1])
  File "/usr/local/lib/python3.8/socket.py", line 669, in readinto
    return self._sock.recv_into(b)
  File "/home/airflow/.local/lib/python3.8/site-packages/airflow/models/taskinstance.py", line 2452, in signal_handler
    raise AirflowException("Task received SIGTERM signal")
airflow.exceptions.AirflowException: Task received SIGTERM signal

During handling of the above exception, another exception occurred:

Traceback (most recent call last):
  File "/home/airflow/.local/lib/python3.8/site-packages/py4j/java_gateway.py", line 1038, in send_command
    response = connection.send_command(command)
  File "/home/airflow/.local/lib/python3.8/site-packages/py4j/clientserver.py", line 539, in send_command
    raise Py4JNetworkError(
py4j.protocol.Py4JNetworkError: Error while sending or receiving
[2025-05-16T00:22:31.492+0000] {clientserver.py:543} INFO - Closing down clientserver connection
[2025-05-16T00:22:31.495+0000] {taskinstance.py:2698} ERROR - Task failed with exception
Traceback (most recent call last):
  File "/home/airflow/.local/lib/python3.8/site-packages/airflow/models/taskinstance.py", line 433, in _execute_task
    result = execute_callable(context=context, **execute_callable_kwargs)
  File "/home/airflow/.local/lib/python3.8/site-packages/airflow/operators/python.py", line 199, in execute
    return_value = self.execute_callable()
  File "/home/airflow/.local/lib/python3.8/site-packages/airflow/operators/python.py", line 216, in execute_callable
    return self.python_callable(*self.op_args, **self.op_kwargs)
  File "/opt/airflow/dags/src/aggregate.py", line 22, in aggregate_to_gold
    df = spark.read.format("delta").load(f"{SILVER_PATH}/date={execution_date}")
  File "/home/airflow/.local/lib/python3.8/site-packages/pyspark/sql/readwriter.py", line 177, in load
    return self._df(self._jreader.load(path))
  File "/home/airflow/.local/lib/python3.8/site-packages/py4j/java_gateway.py", line 1321, in __call__
    return_value = get_return_value(
  File "/home/airflow/.local/lib/python3.8/site-packages/pyspark/sql/utils.py", line 190, in deco
    return f(*a, **kw)
  File "/home/airflow/.local/lib/python3.8/site-packages/py4j/protocol.py", line 334, in get_return_value
    raise Py4JError(
py4j.protocol.Py4JError: An error occurred while calling o47.load
[2025-05-16T00:22:31.747+0000] {taskinstance.py:1138} INFO - Marking task as UP_FOR_RETRY. dag_id=breweries_etl_pipeline, task_id=aggregate_to_gold, execution_date=20250514T000000, start_date=20250516T001525, end_date=20250516T002231
[2025-05-16T00:22:31.921+0000] {standard_task_runner.py:107} ERROR - Failed to execute job 221 for task aggregate_to_gold (An error occurred while calling o47.load; 653)
[2025-05-16T00:22:31.980+0000] {process_utils.py:79} INFO - Process psutil.Process(pid=653, status='terminated', exitcode=1, started='00:15:25') (653) terminated with exit code 1
[2025-05-16T00:22:33.000+0000] {process_utils.py:79} INFO - Process psutil.Process(pid=655, status='terminated', started='00:15:26') (655) terminated with exit code None
[2025-05-16T00:22:33.003+0000] {local_task_job_runner.py:234} INFO - Task exited with return code 143
[2025-05-16T00:22:33.265+0000] {taskinstance.py:3280} INFO - 0 downstream tasks scheduled from follow-on schedule check
